Workbook

Sheet 공고목록
A1: 번호 | B1: 지역 | C1: 대학 | D1: 기관 | E1: 구분 | F1: 공고 제목 | G1: 게시일 | H1: 링크 | I1: 요약 | J1: 게시판 | K1: 출처 | L1: 신뢰도 | M1: 수집일
A2: 1 | B2: 부산 | C2: 경성대학교 | D2: 대학 본부 | E2: 일반강사채용(참고) | F2: 2026학년도 2학기 비전임교원(강사·겸임·초빙) 1차 공개채용 | G2: 2026 | H2: https://apps.ks.ac.kr/eprofappl/eprofappl/index.jsp | I2: 평생교육원 공고 아님. | J2: 교수초빙시스템 | K2: web_search | L2: high | M2: 2026-09-21
A3: 2 | B3: 부산 | C3: 경성대학교 | D3: 평생교육원 | E3: 강좌개설신청 | F3: 2026-2학기 평생교육원 신규강좌 모집 | G3: 2026-04-23 | H3: https://cms1.ks.ac.kr/kscec/bbs/list.do?mId=0208000000&ptIdx=201 | J3: 평생교육원 소식 | K3: scraper | L3: high | M3: 2026-09-21
A4: 3 | B4: 부산 | C4: 고신대학교 | D4: 평생교육원 | E4: 강사모집 | F4: 2022년도 학점은행제 신규 강사모집 안내 | G4: 2022 | H4: https://kosinedu.com/sub04_1/776 | I4: 과거 공고(형식 참고용). | J4: 공지사항 | K4: web_search | L4: high | M4: 2026-09-21
A5: 4 | B5: 부산 | C5: 고신대학교 | D5: 평생교육원 | E5: 강사모집 | F5: 2024년 상반기 고신대학교 평생교육원 학점은행제 신규강사 모집 안내 | G5: 2024 | H5: https://kosinedu.com/sub04_1/2021 | I5: 자격: 학사+교육/연구경력 4년, 석사+2년, 박사. 수강인원 5명(이론 10명) 이상 확보 조건. 국가공무원법 33조 결격사유 없어야 함. 문의 051-990-2260, 2450. (2025·2026 공고는 검색 미확인) | J5: 공지사항 | K5: web_search | L5: high | M5: 2026-09-21
A6: 5 | B6: 부산 | C6: 국립부경대학교 | D6: 평생교육원 | E6: 강좌개설공모 | F6: 2023학년도 2학기 평생교육원 개설강좌 공모 안내 | G6: 2023-05 | H6: https://ee.pknu.ac.kr/ee/1669?action=view&no=9934849 | I6: 공모기간 2023-05-09~05-31. 대상: 교수, 연구원, 대학원생, 직원 등 강의분야 자격·경력 보유자. 매 학기 유사 공모 반복. | J6: 학과 게시판(전재) | K6: web_search | L6: high | M6: 2026-09-21
A7: 6 | B7: 부산 | C7: 국립부경대학교 | D7: 평생교육원 | E7: 강좌개설공모 | F7: 2024학년도 2학기 일반교육과정 개설강좌 공모 | G7: 2024 | H7: http://ps.pknu.ac.kr/ | I7: 평생교육원 홈페이지 공지에 게시된 개설강좌 공모(개별 URL 미확보). 문의 051-629-6791. | J7: 공지사항 | K7: web_search | L7: low | M7: 2026-09-21
A8: 7 | B8: 부산 | C8: 국립부경대학교 | D8: 대학 본부 | E8: 일반강사채용(참고) | F8: 2025-2학기 (1차) 강사 채용 공고 | G8: 2025 | H8: https://kcue.or.kr/notice/sub04.php?pagenumber=1&at=view&idx=657599 | I8: 평생교육원 공고 아님. | J8: 대교협 | K8: web_search | L8: high | M8: 2026-09-21
A9: 8 | B9: 부산 | C9: 국립부경대학교 | D9: 미래교육원(평생교육원) | E9: 강좌개설공모 | F9: 미래교육원 2026학년도 1학기 특별교육과정 개설강좌 공모 | G9: 2025 | H9: https://www.pknu.ac.kr/main/163?action=view&no=723314 | I9: 특별교육과정 개설강좌 공모(강사·강좌 제안). 매 학기 반복. 문의 051-629-6791. | J9: 대학 공지사항 | K9: web_search | L9: high | M9: 2026-09-21
A10: 9 | B10: 부산 | C10: 국립한국해양대학교 | D10: 대학 본부 | E10: 일반강사채용(참고) | F10: 2026학년도 상반기 강사 공개채용 모집 공고 | G10: 2026 | H10: https://www.kmou.ac.kr/kmou/na/ntt/selectNttInfo.do?nttSn=10369063&mi=2035 | I10: 학부 강사 채용. 평생교육원 공고 아님. | J10: 대학 공지사항 | K10: web_search | L10: high | M10: 2026-09-21
A11: 10 | B11: 부산 | C11: 동아대학교 | D11: 평생교육원 | E11: 강좌개설제안(상시) | F11: 강좌개설신청 (홈페이지 상시 접수 메뉴) | H11: https://donga-edu.donga.ac.kr/community_notice/read.aspx?no=10288&board_code=site9100 | J11: 공지사항 | K11: scraper | L11: high | M11: 2026-09-21
A12: 11 | B12: 부산 | C12: 동아대학교 | D12: 대학 본부(교원공채) | E12: 일반강사채용(참고) | F12: 2026학년도 1학기 강사 초빙 공고 | G12: 2026-01 | H12: https://www.jinhakpro.com/recruit/37049 | I12: 접수 2026-01-23 09:00 ~ 01-29 13:00. 기초심사+전공심사(+면접). 평생교육원 공고 아님. | J12: 진학프로 | K12: web_search | L12: high | M12: 2026-09-21
A13: 12 | B13: 부산 | C13: 동의과학대학교 | D13: 평생교육원 | E13: 강사모집 | F13: [평생교육원] 스포츠 강사 채용 공고 (2026년 어르신 스포츠강좌 프로그램 지원사업) | G13: 2026-04-22 | H13: https://m.dit.ac.kr/kr/?idx=17100&mode=view&pCode=notice | I13: 2026년 어르신 스포츠강좌 프로그램 지원사업 강사 채용. 첨부: 강사지원서(hwp). | J13: 대학 공지사항 | K13: web_search | L13: high | M13: 2026-09-21
A14: 13 | B14: 부산 | C14: 동의대학교 | D14: 평생교육원(미래교육원) | E14: 강사모집 | F14: 학점은행제 강사 모집(상시) | H14: https://lifelong.deu.ac.kr/Board/BoardView.aspx?CategoryNo=5&PageNo=1&KeyWord=&KeyField=TITLE&CategoryYN=Y&BoardNo=190984&BoardMstNo=1&MENU_ID=141&Secret=&Secret_YN=N | I14: 제출서류: 지원서(이력서), 연구 및 활동 실적물(최근 2년), 개인정보동의서. 첨부: 학점은행제 강사 자격 기준, 이력서 양식. 평생교육원강사관리위원회가 기초·전공심사 후 필요 시 개별 연락. 문의 051-890-1947~8. | J14: 공지사항 | K14: web_search | L14: high | M14: 2026-09-21
A15: 14 | B15: 부산 | C15: 부산가톨릭대학교 | D15: 평생교육원 | E15: 강사인증/등록 | F15: 2025학년도 강사 인증 신청자 모집 | G15: 2026-01-27 | H15: https://edu.cup.ac.kr/ | I15: 평생교육원 강사 인증(등록) 신청자 모집 공지. 상세는 평생교육원 공지사항 확인. 문의 051-519-0492~4. | J15: 공지사항 | K15: web_search | L15: medium | M15: 2026-09-21
A16: 15 | B16: 부산 | C16: 부산교육대학교 | D16: 대학 본부 | E16: 일반강사채용(참고) | F16: 2025학년도 2학기(1차) 강사 채용공고 | G16: 2025 | H16: https://www.kcue.or.kr/notice/sub04.php?pagenumber=1&at=view&idx=657669 | I16: 평생교육원 공고 아님. | J16: 대교협 | K16: web_search | L16: high | M16: 2026-09-21
A17: 16 | B17: 부산 | C17: 부산대학교 | D17: 미래시민교육원(舊 평생교육원) | E17: 강좌개설제안(상시) | F17: 강좌개설신청 (홈페이지 상시 접수 메뉴) | H17: https://sce.pusan.ac.kr/#none | J17: 미래시민교육원 메인 | K17: scraper | L17: high | M17: 2026-09-21
A18: 17 | B18: 부산 | C18: 부산대학교 | D18: 미래시민교육원 | E18: 강사공지 | F18: 2026학년도 2학기 강사 공지사항 | G18: 2026-08-27 | H18: https://d-sce.pusan.ac.kr/kor/CMS/Board/Board.do?mCode=MN052 | I18: 2학기 강사 대상 공지(학습비 감면 신청 안내와 함께 게시). 강좌개설 신청 절차는 게시판에서 확인 필요. 문의 051-510-1234~5. | J18: 공지사항 | K18: web_search | L18: medium | M18: 2026-09-21
A19: 18 | B19: 부산 | C19: 부산보건대학교 | D19: 평생교육원 | E19: 강좌개설제안(상시) | F19: 신규강좌 개설 신청 (홈페이지 상시 접수 메뉴) | H19: https://life.bhu.ac.kr/ | I19: 홈페이지에 '신규강좌 개설 신청' 메뉴 운영. 문의 051-200-3244, 1528. | J19: 홈페이지 메뉴 | K19: web_search | L19: medium | M19: 2026-09-21
A20: 19 | B20: 부산 | C20: 부산여자대학교 | D20: 대학 본부 | E20: 일반강사채용(참고) | F20: 2025학년도 1학기 2차 강사 공개 채용 공고 | G20: 2025 | H20: https://www.jinhakpro.com/recruit/22963 | I20: 평생교육원 공고 아님. | J20: 진학프로 | K20: web_search | L20: high | M20: 2026-09-21
A21: 20 | B21: 부산 | C21: 부산예술대학교 | D21: 평생교육원 | E21: 강사모집 | F21: 2025학년도 여름학기 평생교육원 개설강좌 및 강사모집 공고 | H21: https://pia-edu.com/notice/?bmode=view&idx=161131935 | I21: 여름학기 개설강좌 및 강사 공모 공고(게시글 URL 확보). | J21: 공지사항 | K21: web_search | L21: high | M21: 2026-09-21
A22: 21 | B22: 부산 | C22: 부산예술대학교 | D22: 평생교육원 | E22: 강사모집 | F22: 2025학년도 겨울학기 평생교육원 개설강좌 및 강사모집 공고 | G22: 2025-10-21 | H22: https://pia-edu.com/notice/?bmode=view&idx=168278318 | I22: 겨울학기 개설강좌 및 강사 공모 공고(게시글 URL 확보). | J22: 공지사항 | K22: web_search | L22: high | M22: 2026-09-21
A23: 22 | B23: 부산 | C23: 부산예술대학교 | D23: 평생교육원 | E23: 강사모집 | F23: 2026학년도 1학기 평생교육원 개설강좌 및 강사모집 공고 | G23: 2026-01-19 | H23: https://pia-edu.com/notice/?q=YToxOntzOjEyOiJrZXl3b3JkX3R5cGUiO3M6MzoiYWxsIjt9&bmode=view&idx=169560243&t=board | I23: 학기별로 개설강좌와 강사를 함께 공모하는 정기 공고. 검색 스니펫에서 제목만 확인되어 개별 게시글 URL은 공지 목록에서 확인 필요. 문의 051-622-0056 / 051-628-3990. | J23: 공지사항 | K23: web_search | L23: medium | M23: 2026-09-21
A24: 23 | B24: 부산 | C24: 부산예술대학교 | D24: 평생교육원 | E24: 강사모집 | F24: 2026학년도 여름학기 평생교육원 개설강좌 및 강사모집 공고 | G24: 2026-05-12 | H24: https://pia-edu.com/notice/?q=YToxOntzOjEyOiJrZXl3b3JkX3R5cGUiO3M6MzoiYWxsIjt9&bmode=view&idx=171246486&t=board | J24: 공지사항 | K24: scraper | L24: high | M24: 2026-09-21
A25: 24 | B25: 부산 | C25: 부산외국어대학교 | D25: 평생교육원 | E25: 강사모집 | F25: 2021학년도 평생교육 여름학기 정규강좌 신규 강좌 및 강사 모집 | G25: 2021 | H25: https://lec.bufs.ac.kr/lec/index.php?pCode=MN000017&mode=view&idx=66631 | I25: 정규강좌 및 민간자격증 과정 신규 강좌·강사 모집(과거 공고, 게시판 위치 참고). | J25: 공지사항 | K25: web_search | L25: high | M25: 2026-09-21
A26: 25 | B26: 부산 | C26: 신라대학교 | D26: 평생교육원 | E26: 강좌개설신청 | F26: 2026학년도 2학기 평생교육부 강좌 개설 희망자 모집 및 서류 제출 안내 | G26: 2026-08-03 | H26: https://soc.silla.ac.kr/Home/Sub04/NoticeBoard01.aspx?id=1116 | J26: 공지사항 | K26: scraper | L26: high | M26: 2026-09-21
A27: 26 | B27: 부산 | C27: 영산대학교 | D27: 평생교육원 | E27: 강사모집 | F27: 2025년도 봄학기 일반과정 신규강좌 및 강사모집 | G27: 2025 | H27: https://ysedu.ysu.ac.kr/board/notice_edu/list.asp | I27: 학기별 신규강좌·강사 모집. 강좌개설 신청은 교양·건강·스포츠·컴퓨터·창업 등 전 분야 가능. 문의 051-540-7045, 7265. | J27: 공지사항 | K27: web_search | L27: medium | M27: 2026-09-21
A28: 27 | B28: 부산 | C28: 영산대학교 | D28: 대학 본부 | E28: 일반강사채용(참고) | F28: 2026학년도 하반기 겸임교수 공개채용 공고 | G28: 2026 | H28: https://www.jinhakpro.com/recruit/45759 | I28: 평생교육원 공고 아님. | J28: 진학프로 | K28: web_search | L28: high | M28: 2026-09-21
A29: 28 | B29: 울산 | C29: 울산과학대학교 | D29: 평생교육원 | E29: 강좌개설제안(상시) | F29: 강좌 개설 제안 (홈페이지 상시 접수 메뉴) | H29: https://edu.uc.ac.kr/edu/CMS/Board/Board.do?mCode=MN080 | J29: 공지사항 | K29: scraper | L29: high | M29: 2026-09-21
A30: 29 | B30: 울산 | C30: 울산과학대학교 | D30: 평생교육원 | E30: 강좌개설제안(상시) | F30: 강좌개설제안 (홈페이지 상시 접수 메뉴) | H30: https://www.uc.ac.kr/edu/ | I30: 별도 공고 없이 홈페이지 '강좌개설제안' 메뉴로 프로그램 개설 제안을 상시 접수. 문의 052-230-0822. | J30: 홈페이지 메뉴 | K30: web_search | L30: medium | M30: 2026-09-21
A31: 30 | B31: 울산 | C31: 울산대학교 | D31: 평생교육원 | E31: 강사모집 | F31: 2025년 하반기 평생교육 강사 위수탁 추가모집 공고 | G31: 2025 | H31: https://cec.ulsan.ac.kr/cec/3978?action=view&no=272609 | I31: 하반기 강사 위수탁 추가모집. 게시글 번호(no=272609)는 검색 결과 기준 추정. | J31: 공지사항 | K31: web_search | L31: medium | M31: 2026-09-21
A32: 31 | B32: 울산 | C32: 울산대학교 | D32: 평생교육원 | E32: 강좌개설제안(상시) | F32: 신규 강좌 개설 제안서 안내 | G32: 2025-09-26 | H32: https://cec.ulsan.ac.kr/cec/3978?action=view&no=270342 | I32: 평생교육 전 분야 대상 상시 접수. 홈페이지 '강좌개설제안서' 제출 → 전화 확인 → 운영위원회 심의 → 개설 확정 시 개별 연락. 문의 052-259-2018, 2020 / cec2020@mail.ulsan.ac.kr. | J32: 공지사항 | K32: web_search | L32: high | M32: 2026-09-21
A33: 32 | B33: 경남 | C33: 가야대학교 | D33: 평생교육원 | E33: 강사인증/등록 | F33: 강사지원 (홈페이지 상시 접수 메뉴) | H33: https://life.kaya.ac.kr/pages/applicant/application.jsp | I33: 평생교육원 홈페이지에 '강사지원' 메뉴 운영(상시). 문의 055-344-5210. | J33: 홈페이지 메뉴 | K33: web_search | L33: medium | M33: 2026-09-21
A34: 33 | B34: 경남 | C34: 경남대학교 | D34: 평생교육원 | E34: 강사인증/등록 | F34: 창원시 평생학습정보망 강사등록 안내 | H34: https://www.kyungnam.ac.kr/cce/3489/subview.do?enc=Zm5jdDF8QEB8JTJGYmJzJTJGY2NlJTJGMjQxJTJGMTgxMzkxJTJGYXJ0Y2xWaWV3LmRvJTNG | I34: 창원시 평생학습정보망(강사은행) 강사 등록 방법 안내. | J34: 공지사항 | K34: web_search | L34: medium | M34: 2026-09-21
A35: 34 | B35: 경남 | C35: 경남대학교 | D35: 평생교육원 | E35: 강사모집 | F35: 2026년 여름방학특강 개설 교강사 모집 | G35: 2026 | H35: https://www.kyungnam.ac.kr/cce/14630/subview.do | I35: 평생교육원 채용공고 게시판에 게시. 문의 055-249-2720. | J35: 채용공고 | K35: web_search | L35: medium | M35: 2026-09-21
A36: 35 | B36: 경남 | C36: 경상국립대학교 | D36: 평생교육원 | E36: 강좌개설신청 | F36: [강사공지] 2026년도 2학기 강좌 개설 신청 안내 | G36: 2026-06-02 | H36: https://longlife.gnu.ac.kr/sub.jsp?sID=0201 | I36: 2학기 강좌 개설(강사) 신청 안내. 홈페이지 '강좌개설신청' 메뉴로 접수. | J36: 강사공지 | K36: web_search | L36: high | M36: 2026-09-21
A37: 36 | B37: 경남 | C37: 국립창원대학교 | D37: 평생교육원 | E37: 강사공지 | F37: 자료실 > 강사 (강사용 서식·안내 게시판) | H37: https://www.changwon.ac.kr/lifelong/na/ntt/selectNttList.do?mi=4771&bbsId=1786 | I37: 강사 대상 서식·안내 게시판. 공개 강사모집 공고는 검색에서 미확인. 문의 055-213-2561~5. | J37: 자료실 | K37: web_search | L37: medium | M37: 2026-09-21
A38: 37 | B38: 경남 | C38: 국립창원대학교 | D38: 평생교육원 | E38: 강좌개설공모 | F38: 2026학년도 제2학기 신규 개설강좌 공모 | G38: 2026-05-13 | H38: https://www.changwon.ac.kr/lifelong/na/ntt/selectNttList.do?mi=4774&bbsId=1787 | J38: 공지사항 | K38: scraper | L38: medium | M38: 2026-09-21
A39: 38 | B39: 경남 | C39: 마산대학교 | D39: 평생교육원 | E39: 강좌개설제안(상시) | F39: 강좌 개설 신청 (홈페이지 상시 접수 메뉴) | H39: https://lifelong.masan.ac.kr/lectopen | J39: 공지사항 | K39: scraper | L39: high | M39: 2026-09-21
A40: 39 | B40: 경남 | C40: 마산대학교 | D40: 평생교육원 | E40: 강좌개설공모 | F40: [직업능력교육] 2025학년도 2학기 창원시 · 함안군 및 창녕군 위탁 평생교육과정 신규강좌 개설 제안 공모 안내 | G40: 2025-06-12 | H40: https://lifelong.masan.ac.kr/lectopen/view/2025/20/010/999/13 | J40: 공지사항 | K40: scraper | L40: high | M40: 2026-09-21
...

Sheet 기관목록
A1: 지역 | B1: 대학 | C1: 기관 | D1: 홈페이지 | E1: 공고 게시판 | F1: 전화 | G1: 이메일 | H1: 수집 공고 수(참고 제외)
A2: 부산 | B2: 경남정보대학교 | C2: 평생교육원 | D2: https://cei.kit.ac.kr/cei/ | E2: 공지사항: https://cei.kit.ac.kr/cei/?pCode=MN0000028 | F2: 051-320-1367 | H2: =COUNTIFS(공고목록!$C:$C,B2,공고목록!$E:$E,"<>일반강사채용(참고)") -> 0
A3: 부산 | B3: 경성대학교 | C3: 평생교육원 | D3: https://cms1.ks.ac.kr/kscec/Main.do | E3: 평생교육원 소식: https://cms1.ks.ac.kr/kscec/bbs/list.do?mId=0208000000&ptIdx=201 | F3: 051-663-5311~7 | H3: =COUNTIFS(공고목록!$C:$C,B3,공고목록!$E:$E,"<>일반강사채용(참고)") -> 1
A4: 부산 | B4: 고신대학교 | C4: 평생교육원 | D4: https://kosinedu.com/ | E4: 공지사항(학점은행제): https://kosinedu.com/index.php?mid=sub04_1&order_type=desc | F4: 051-990-2260, 2219 | H4: =COUNTIFS(공고목록!$C:$C,B4,공고목록!$E:$E,"<>일반강사채용(참고)") -> 2
A5: 부산 | B5: 국립부경대학교 | C5: 평생교육원 | D5: http://ps.pknu.ac.kr/ | E5: 대학 공지사항: https://www.pknu.ac.kr/main/163 | F5: 051-629-6791 | H5: =COUNTIFS(공고목록!$C:$C,B5,공고목록!$E:$E,"<>일반강사채용(참고)") -> 3
A6: 부산 | B6: 국립한국해양대학교 | C6: 평생교육원 | D6: https://www.kmou.ac.kr/edu/main.do | E6: 평생교육원 메인: https://www.kmou.ac.kr/edu/main.do | H6: =COUNTIFS(공고목록!$C:$C,B6,공고목록!$E:$E,"<>일반강사채용(참고)") -> 0
A7: 부산 | B7: 동서대학교 | C7: 평생교육원 | D7: https://uni.dongseo.ac.kr/continuing/ | E7: 대학 모집공고: https://www.dongseo.ac.kr/kr/index.php?pCode=MN2000197&CgCode=A5 | H7: =COUNTIFS(공고목록!$C:$C,B7,공고목록!$E:$E,"<>일반강사채용(참고)") -> 0
A8: 부산 | B8: 동아대학교 | C8: 평생교육원 | D8: https://donga-edu.donga.ac.kr/ | E8: 공지사항: https://donga-edu.donga.ac.kr/main/main.aspx | F8: 051-200-8452~6 | H8: =COUNTIFS(공고목록!$C:$C,B8,공고목록!$E:$E,"<>일반강사채용(참고)") -> 1
A9: 부산 | B9: 동의과학대학교 | C9: 평생교육원 | D9: https://ce.dit.ac.kr/dit/ | E9: 공지사항: https://ce.dit.ac.kr/dit/?pCode=MN0000014 대학 공지사항: https://m.dit.ac.kr/kr/?pCode=notice | H9: =COUNTIFS(공고목록!$C:$C,B9,공고목록!$E:$E,"<>일반강사채용(참고)") -> 1
A10: 부산 | B10: 동의대학교 | C10: 평생교육원(미래교육원) | D10: https://lifelong.deu.ac.kr/ | E10: 공지사항: https://lifelong.deu.ac.kr/Board/BoardList.aspx?BoardMstNo=1&MENU_ID=141 | F10: 051-890-1947~8 | H10: =COUNTIFS(공고목록!$C:$C,B10,공고목록!$E:$E,"<>일반강사채용(참고)") -> 1
A11: 부산 | B11: 부산가톨릭대학교 | C11: 평생교육원 | D11: https://edu.cup.ac.kr/ | E11: 공지사항: https://edu.cup.ac.kr/ | F11: 051-519-0492~4 | H11: =COUNTIFS(공고목록!$C:$C,B11,공고목록!$E:$E,"<>일반강사채용(참고)") -> 1
A12: 부산 | B12: 부산경상대학교 | C12: 평생교육원 | D12: https://www.bsks.ac.kr/ | E12: (게시판 URL 미확인) | H12: =COUNTIFS(공고목록!$C:$C,B12,공고목록!$E:$E,"<>일반강사채용(참고)") -> 0
A13: 부산 | B13: 부산과학기술대학교 | C13: 평생교육원 | D13: https://life.bist.ac.kr/ | E13: 공지사항: https://life.bist.ac.kr/ | H13: =COUNTIFS(공고목록!$C:$C,B13,공고목록!$E:$E,"<>일반강사채용(참고)") -> 0
A14: 부산 | B14: 부산교육대학교 | C14: 평생교육원 | D14: https://www.bnue.ac.kr/ | E14: 신청포털: https://apply.bnue.ac.kr/home/main | H14: =COUNTIFS(공고목록!$C:$C,B14,공고목록!$E:$E,"<>일반강사채용(참고)") -> 0
A15: 부산 | B15: 부산대학교 | C15: 미래시민교육원(舊 평생교육원) | D15: https://sce.pusan.ac.kr/ | E15: 미래시민교육원 메인: https://sce.pusan.ac.kr/ 공지사항: https://d-sce.pusan.ac.kr/kor/CMS/Board/Board.do?mCode=MN052 | F15: 051-510-1234~5, 1353~4 | H15: =COUNTIFS(공고목록!$C:$C,B15,공고목록!$E:$E,"<>일반강사채용(참고)") -> 2
A16: 부산 | B16: 부산디지털대학교 | C16: 평생교육원 | D16: http://www.bdu.ac.kr/edulife/index.do | E16: 대학 공지: https://www.bdu.ac.kr/bduhome/sub03_06_03_01.do | H16: =COUNTIFS(공고목록!$C:$C,B16,공고목록!$E:$E,"<>일반강사채용(참고)") -> 0
A17: 부산 | B17: 부산보건대학교 | C17: 평생교육원 | D17: https://life.bhu.ac.kr/ | E17: 공지사항: https://life.bhu.ac.kr/Board/BoardList.aspx?BoardMstNo=1&MENU_ID=24 | F17: 051-200-3244, 1528 | H17: =COUNTIFS(공고목록!$C:$C,B17,공고목록!$E:$E,"<>일반강사채용(참고)") -> 1
A18: 부산 | B18: 부산여자대학교 | C18: 평생교육원 | D18: https://www.bwc.ac.kr/ | E18: (게시판 URL 미확인) | H18: =COUNTIFS(공고목록!$C:$C,B18,공고목록!$E:$E,"<>일반강사채용(참고)") -> 0
A19: 부산 | B19: 부산예술대학교 | C19: 평생교육원 | D19: https://pia-edu.com/ | E19: 공지사항: https://pia-edu.com/notice/ | F19: 051-622-0056, 051-628-3990 | H19: =COUNTIFS(공고목록!$C:$C,B19,공고목록!$E:$E,"<>일반강사채용(참고)") -> 4
A20: 부산 | B20: 부산외국어대학교 | C20: 평생교육원 | D20: https://lec.bufs.ac.kr/ | E20: 홈페이지(공지): https://lec.bufs.ac.kr/ | H20: =COUNTIFS(공고목록!$C:$C,B20,공고목록!$E:$E,"<>일반강사채용(참고)") -> 1
A21: 부산 | B21: 신라대학교 | C21: 평생교육원 | D21: https://soc.silla.ac.kr/ | E21: 공지사항: https://soc.silla.ac.kr/ | H21: =COUNTIFS(공고목록!$C:$C,B21,공고목록!$E:$E,"<>일반강사채용(참고)") -> 1
A22: 부산 | B22: 영산대학교 | C22: 평생교육원(해운대/양산) | D22: https://ysedu.ysu.ac.kr/ | E22: 공지사항: https://ysedu.ysu.ac.kr/board/notice_edu/list.asp | F22: 051-540-7045, 7265 | H22: =COUNTIFS(공고목록!$C:$C,B22,공고목록!$E:$E,"<>일반강사채용(참고)") -> 1
A23: 울산 | B23: 울산과학대학교 | C23: 평생교육원 | D23: https://www.uc.ac.kr/edu/ | E23: 공지사항: https://edu.uc.ac.kr/edu/Main.do 강좌개설제안: https://edu.uc.ac.kr/edu/CMS/Board/Board.do?mCode=MN080 | F23: 052-230-0822 | H23: =COUNTIFS(공고목록!$C:$C,B23,공고목록!$E:$E,"<>일반강사채용(참고)") -> 2
A24: 울산 | B24: 울산대학교 | C24: 평생교육원 | D24: https://cec.ulsan.ac.kr/cec | E24: 공지사항: https://cec.ulsan.ac.kr/cec/3978 | F24: 052-259-2018, 2020 | G24: cec2020@mail.ulsan.ac.kr | H24: =COUNTIFS(공고목록!$C:$C,B24,공고목록!$E:$E,"<>일반강사채용(참고)") -> 2
A25: 울산 | B25: 춘해보건대학교 | C25: 평생교육원 | D25: https://edu.ch.ac.kr/ | E25: 공지사항: https://edu.ch.ac.kr/ | H25: =COUNTIFS(공고목록!$C:$C,B25,공고목록!$E:$E,"<>일반강사채용(참고)") -> 0
A26: 경남 | B26: 가야대학교 | C26: 평생교육원 | D26: https://life.kaya.ac.kr/ | E26: 강사지원: https://life.kaya.ac.kr/pages/applicant/application.jsp | F26: 055-344-5210 | H26: =COUNTIFS(공고목록!$C:$C,B26,공고목록!$E:$E,"<>일반강사채용(참고)") -> 1
A27: 경남 | B27: 거제대학교 | C27: 평생교육원 | D27: https://www.koje.ac.kr/ | E27: (게시판 URL 미확인) | H27: =COUNTIFS(공고목록!$C:$C,B27,공고목록!$E:$E,"<>일반강사채용(참고)") -> 0
A28: 경남 | B28: 경남대학교 | C28: 평생교육원 | D28: https://www.kyungnam.ac.kr/sites/cce/index..do | E28: 채용공고: https://www.kyungnam.ac.kr/cce/14630/subview.do 공지사항: https://www.kyungnam.ac.kr/cce/3489/subview.do | F28: 055-249-2720 | H28: =COUNTIFS(공고목록!$C:$C,B28,공고목록!$E:$E,"<>일반강사채용(참고)") -> 2
A29: 경남 | B29: 경상국립대학교 | C29: 평생교육원 | D29: https://longlife.gnu.ac.kr/ | E29: 강사공지: https://longlife.gnu.ac.kr/sub.jsp?sID=0201 | H29: =COUNTIFS(공고목록!$C:$C,B29,공고목록!$E:$E,"<>일반강사채용(참고)") -> 1
A30: 경남 | B30: 국립창원대학교 | C30: 평생교육원 | D30: https://www.changwon.ac.kr/lifelong/main.do | E30: 공지사항: https://www.changwon.ac.kr/lifelong/na/ntt/selectNttList.do?mi=4774&bbsId=1787 자료실>강사: https://www.changwon.ac.kr/lifelong/na/ntt/selectNttList.do?mi=4771&bbsId=1786 | F30: 055-213-2561~5 | H30: =COUNTIFS(공고목록!$C:$C,B30,공고목록!$E:$E,"<>일반강사채용(참고)") -> 2
A31: 경남 | B31: 국립창원대학교 거창캠퍼스 | C31: 평생교육원 | D31: https://psl.gc.ac.kr/M0101/ | E31: (게시판 URL 미확인) | H31: =COUNTIFS(공고목록!$C:$C,B31,공고목록!$E:$E,"<>일반강사채용(참고)") -> 0
A32: 경남 | B32: 김해대학교 | C32: 평생교육원 | D32: https://www.gimhae.ac.kr/ | E32: (게시판 URL 미확인) | H32: =COUNTIFS(공고목록!$C:$C,B32,공고목록!$E:$E,"<>일반강사채용(참고)") -> 0
A33: 경남 | B33: 동원과학기술대학교 | C33: 평생교육원 | D33: https://www.dongwon.ac.kr/ | E33: (게시판 URL 미확인) | H33: =COUNTIFS(공고목록!$C:$C,B33,공고목록!$E:$E,"<>일반강사채용(참고)") -> 0
A34: 경남 | B34: 마산대학교 | C34: 평생교육원 | D34: https://lifelong.masan.ac.kr/main | E34: 강좌개설신청: https://lifelong.masan.ac.kr/lectopen | H34: =COUNTIFS(공고목록!$C:$C,B34,공고목록!$E:$E,"<>일반강사채용(참고)") -> 3
A35: 경남 | B35: 연암공과대학교 | C35: 평생교육원 | D35: https://www.yc.ac.kr/ | E35: (게시판 URL 미확인) | H35: =COUNTIFS(공고목록!$C:$C,B35,공고목록!$E:$E,"<>일반강사채용(참고)") -> 0
A36: 경남 | B36: 인제대학교 | C36: 평생교육원(미래교육원) | D36: https://soc.inje.ac.kr/ | E36: 대학 모집/채용: https://www.inje.ac.kr/kor/Template/Bsub_page.asp?Ltype=5&Ltype2=0&Ltype3=0&Tname=S_News&Ldir=board/S_News&div=8&d1n=5&d2n=1&d3n=3&d4n=0 | H36: =COUNTIFS(공고목록!$C:$C,B36,공고목록!$E:$E,"<>일반강사채용(참고)") -> 0
A37: 경남 | B37: 진주보건대학교 | C37: 평생교육원 | D37: https://lifelong.jhc.ac.kr/ | E37: 공지사항: https://lifelong.jhc.ac.kr/bbs/board.php?bo_table=sub4_1 | F37: 055-740-1756 | H37: =COUNTIFS(공고목록!$C:$C,B37,공고목록!$E:$E,"<>일반강사채용(참고)") -> 1
A38: 경남 | B38: 창신대학교 | C38: 평생교육원 | D38: https://ice.cs.ac.kr/ | E38: 평생교육원 메인: https://ice.cs.ac.kr/ | F38: 055-250-3050 | H38: =COUNTIFS(공고목록!$C:$C,B38,공고목록!$E:$E,"<>일반강사채용(참고)") -> 0
A39: 경남 | B39: 창원문성대학교 | C39: 평생교육원 | D39: https://www.cmu.ac.kr/ | E39: (게시판 URL 미확인) | H39: =COUNTIFS(공고목록!$C:$C,B39,공고목록!$E:$E,"<>일반강사채용(참고)") -> 0

Sheet 요약
A1: 지역 × 구분별 공고 건수 (공고목록 시트 기준 자동 집계)
A3: 지역 | B3: 강사모집 | C3: 강좌개설신청 | D3: 강좌개설공모 | E3: 강좌개설제안(상시) | F3: 강사인증/등록 | G3: 강사공지 | H3: 일반강사채용(참고) | I3: 합계
A4: 부산 | B4: =COUNTIFS(공고목록!$B:$B,$A4,공고목록!$E:$E,B$3) -> 10 | C4: =COUNTIFS(공고목록!$B:$B,$A4,공고목록!$E:$E,C$3) -> 2 | D4: =COUNTIFS(공고목록!$B:$B,$A4,공고목록!$E:$E,D$3) -> 3 | E4: =COUNTIFS(공고목록!$B:$B,$A4,공고목록!$E:$E,E$3) -> 3 | F4: =COUNTIFS(공고목록!$B:$B,$A4,공고목록!$E:$E,F$3) -> 1 | G4: =COUNTIFS(공고목록!$B:$B,$A4,공고목록!$E:$E,G$3) -> 1 | H4: =COUNTIFS(공고목록!$B:$B,$A4,공고목록!$E:$E,H$3) -> 7 | I4: =SUM(B4:H4) -> 27
A5: 울산 | B5: =COUNTIFS(공고목록!$B:$B,$A5,공고목록!$E:$E,B$3) -> 1 | C5: =COUNTIFS(공고목록!$B:$B,$A5,공고목록!$E:$E,C$3) -> 0 | D5: =COUNTIFS(공고목록!$B:$B,$A5,공고목록!$E:$E,D$3) -> 0 | E5: =COUNTIFS(공고목록!$B:$B,$A5,공고목록!$E:$E,E$3) -> 3 | F5: =COUNTIFS(공고목록!$B:$B,$A5,공고목록!$E:$E,F$3) -> 0 | G5: =COUNTIFS(공고목록!$B:$B,$A5,공고목록!$E:$E,G$3) -> 0 | H5: =COUNTIFS(공고목록!$B:$B,$A5,공고목록!$E:$E,H$3) -> 0 | I5: =SUM(B5:H5) -> 4
A6: 경남 | B6: =COUNTIFS(공고목록!$B:$B,$A6,공고목록!$E:$E,B$3) -> 1 | C6: =COUNTIFS(공고목록!$B:$B,$A6,공고목록!$E:$E,C$3) -> 2 | D6: =COUNTIFS(공고목록!$B:$B,$A6,공고목록!$E:$E,D$3) -> 3 | E6: =COUNTIFS(공고목록!$B:$B,$A6,공고목록!$E:$E,E$3) -> 1 | F6: =COUNTIFS(공고목록!$B:$B,$A6,공고목록!$E:$E,F$3) -> 2 | G6: =COUNTIFS(공고목록!$B:$B,$A6,공고목록!$E:$E,G$3) -> 1 | H6: =COUNTIFS(공고목록!$B:$B,$A6,공고목록!$E:$E,H$3) -> 1 | I6: =SUM(B6:H6) -> 11
A7: 합계 | B7: =SUM(B4:B6) -> 12 | C7: =SUM(C4:C6) -> 4 | D7: =SUM(D4:D6) -> 6 | E7: =SUM(E4:E6) -> 7 | F7: =SUM(F4:F6) -> 3 | G7: =SUM(G4:G6) -> 2 | H7: =SUM(H4:H6) -> 8 | I7: =SUM(I4:I6) -> 42
A9: 구분 설명
A10: 강사모집: 강사를 직접 공모하는 공고 / 강좌개설신청·공모: 강사가 강좌 개설을 신청하는 방식의 학기별 공고
A11: 강좌개설제안(상시): 공고 없이 홈페이지 메뉴로 상시 접수 / 강사인증/등록: 강사 풀 등록 / 강사공지: 기존 강사 대상 안내
A12: 일반강사채용(참고): 평생교육원이 아닌 대학 본부의 학부 강사·겸임교수 채용 (참고용)
A13: 신뢰도: high = 게시글 URL까지 확인, medium = 제목·게시판만 확인, low = 검색 스니펫으로만 확인
A14: 출처 web_search: 대학 도메인 직접 접속이 차단된 환경에서 웹 검색 결과로 수집 / scraper: 자동 수집
